<?xml version="1.0" encoding="UTF-8"?>
<!-- Generated by org.testng.reporters.JUnitXMLReporter -->
<testsuite ignored="0" hostname="INSUPLTQAPT" failures="1" tests="3" name="LoginTest" time="0.071" errors="0" timestamp="2024-08-06T21:35:20 IST">
  <testcase classname="reexecutiononfailure.LoginTest" name="doLogin" time="0.017">
    <skipped/>
  </testcase> <!-- doLogin -->
  <testcase classname="reexecutiononfailure.LoginTest" name="doLogin" time="0.002">
    <skipped/>
  </testcase> <!-- doLogin -->
  <testcase classname="reexecutiononfailure.LoginTest" name="doLogin" time="0.002">
    <failure type="java.lang.AssertionError" message="expected [4] but found [3]">
      <![CDATA[java.lang.AssertionError: expected [4] but found [3]
at reexecutiononfailure.LoginTest.doLogin(LoginTest.java:14)
at java.base/java.util.ArrayList.forEach(ArrayList.java:1596)
... Removed 32 stack frames]]>
    </failure>
  </testcase> <!-- doLogin -->
</testsuite> <!-- LoginTest -->
